[2023-03-08T07:39:31.615+0000] {taskinstance.py:1083} INFO - Dependencies all met for <TaskInstance: dag_with_api.http_get scheduled__2023-03-06T00:00:00+00:00 [queued]>
[2023-03-08T07:39:31.673+0000] {taskinstance.py:1083} INFO - Dependencies all met for <TaskInstance: dag_with_api.http_get scheduled__2023-03-06T00:00:00+00:00 [queued]>
[2023-03-08T07:39:31.683+0000] {taskinstance.py:1279} INFO - 
--------------------------------------------------------------------------------
[2023-03-08T07:39:31.700+0000] {taskinstance.py:1280} INFO - Starting attempt 3 of 6
[2023-03-08T07:39:31.707+0000] {taskinstance.py:1281} INFO - 
--------------------------------------------------------------------------------
[2023-03-08T07:39:31.756+0000] {taskinstance.py:1300} INFO - Executing <Task(SimpleHttpOperator): http_get> on 2023-03-06 00:00:00+00:00
[2023-03-08T07:39:31.786+0000] {standard_task_runner.py:55} INFO - Started process 567 to run task
[2023-03-08T07:39:31.806+0000] {standard_task_runner.py:82} INFO - Running: ['***', 'tasks', 'run', 'dag_with_api', 'http_get', 'scheduled__2023-03-06T00:00:00+00:00', '--job-id', '51', '--raw', '--subdir', 'DAGS_FOLDER/django_dag.py', '--cfg-path', '/tmp/tmpzi2zrae9']
[2023-03-08T07:39:31.809+0000] {standard_task_runner.py:83} INFO - Job 51: Subtask http_get
[2023-03-08T07:39:32.052+0000] {task_command.py:388} INFO - Running <TaskInstance: dag_with_api.http_get scheduled__2023-03-06T00:00:00+00:00 [running]> on host 99e079803755
[2023-03-08T07:39:32.226+0000] {taskinstance.py:1509} INFO - Exporting the following env vars:
AIRFLOW_CTX_DAG_OWNER=***
AIRFLOW_CTX_DAG_ID=dag_with_api
AIRFLOW_CTX_TASK_ID=http_get
AIRFLOW_CTX_EXECUTION_DATE=2023-03-06T00:00:00+00:00
AIRFLOW_CTX_TRY_NUMBER=3
AIRFLOW_CTX_DAG_RUN_ID=scheduled__2023-03-06T00:00:00+00:00
[2023-03-08T07:39:32.231+0000] {http.py:123} INFO - Calling HTTP method
[2023-03-08T07:39:32.251+0000] {base.py:73} INFO - Using connection ID 'django_api' for task execution.
[2023-03-08T07:39:32.269+0000] {http.py:208} WARNING - HTTPConnectionPool(host='127.0.0.1', port=8000): Max retries exceeded with url: /:8000/endpoint_path (Caused by NewConnectionError('<urllib3.connection.HTTPConnection object at 0xffff831c0c90>: Failed to establish a new connection: [Errno 111] Connection refused')) Tenacity will retry to execute the operation
[2023-03-08T07:39:32.272+0000] {taskinstance.py:1768} ERROR - Task failed with exception
Traceback (most recent call last):
  File "/home/airflow/.local/lib/python3.7/site-packages/urllib3/connection.py", line 175, in _new_conn
    (self._dns_host, self.port), self.timeout, **extra_kw
  File "/home/airflow/.local/lib/python3.7/site-packages/urllib3/util/connection.py", line 95, in create_connection
    raise err
  File "/home/airflow/.local/lib/python3.7/site-packages/urllib3/util/connection.py", line 85, in create_connection
    sock.connect(sa)
ConnectionRefusedError: [Errno 111] Connection refused

During handling of the above exception, another exception occurred:

Traceback (most recent call last):
  File "/home/airflow/.local/lib/python3.7/site-packages/urllib3/connectionpool.py", line 710, in urlopen
    chunked=chunked,
  File "/home/airflow/.local/lib/python3.7/site-packages/urllib3/connectionpool.py", line 398, in _make_request
    conn.request(method, url, **httplib_request_kw)
  File "/home/airflow/.local/lib/python3.7/site-packages/urllib3/connection.py", line 239, in request
    super(HTTPConnection, self).request(method, url, body=body, headers=headers)
  File "/usr/local/lib/python3.7/http/client.py", line 1281, in request
    self._send_request(method, url, body, headers, encode_chunked)
  File "/usr/local/lib/python3.7/http/client.py", line 1327, in _send_request
    self.endheaders(body, encode_chunked=encode_chunked)
  File "/usr/local/lib/python3.7/http/client.py", line 1276, in endheaders
    self._send_output(message_body, encode_chunked=encode_chunked)
  File "/usr/local/lib/python3.7/http/client.py", line 1036, in _send_output
    self.send(msg)
  File "/usr/local/lib/python3.7/http/client.py", line 976, in send
    self.connect()
  File "/home/airflow/.local/lib/python3.7/site-packages/urllib3/connection.py", line 205, in connect
    conn = self._new_conn()
  File "/home/airflow/.local/lib/python3.7/site-packages/urllib3/connection.py", line 187, in _new_conn
    self, "Failed to establish a new connection: %s" % e
urllib3.exceptions.NewConnectionError: <urllib3.connection.HTTPConnection object at 0xffff831c0c90>: Failed to establish a new connection: [Errno 111] Connection refused

During handling of the above exception, another exception occurred:

Traceback (most recent call last):
  File "/home/airflow/.local/lib/python3.7/site-packages/requests/adapters.py", line 499, in send
    timeout=timeout,
  File "/home/airflow/.local/lib/python3.7/site-packages/urllib3/connectionpool.py", line 788, in urlopen
    method, url, error=e, _pool=self, _stacktrace=sys.exc_info()[2]
  File "/home/airflow/.local/lib/python3.7/site-packages/urllib3/util/retry.py", line 592, in increment
    raise MaxRetryError(_pool, url, error or ResponseError(cause))
urllib3.exceptions.MaxRetryError: HTTPConnectionPool(host='127.0.0.1', port=8000): Max retries exceeded with url: /:8000/endpoint_path (Caused by NewConnectionError('<urllib3.connection.HTTPConnection object at 0xffff831c0c90>: Failed to establish a new connection: [Errno 111] Connection refused'))

During handling of the above exception, another exception occurred:

Traceback (most recent call last):
  File "/home/airflow/.local/lib/python3.7/site-packages/airflow/providers/http/operators/http.py", line 125, in execute
    response = http.run(self.endpoint, self.data, self.headers, self.extra_options)
  File "/home/airflow/.local/lib/python3.7/site-packages/airflow/providers/http/hooks/http.py", line 151, in run
    return self.run_and_check(session, prepped_request, extra_options)
  File "/home/airflow/.local/lib/python3.7/site-packages/airflow/providers/http/hooks/http.py", line 209, in run_and_check
    raise ex
  File "/home/airflow/.local/lib/python3.7/site-packages/airflow/providers/http/hooks/http.py", line 201, in run_and_check
    response = session.send(prepped_request, **send_kwargs)
  File "/home/airflow/.local/lib/python3.7/site-packages/requests/sessions.py", line 701, in send
    r = adapter.send(request, **kwargs)
  File "/home/airflow/.local/lib/python3.7/site-packages/requests/adapters.py", line 565, in send
    raise ConnectionError(e, request=request)
requests.exceptions.ConnectionError: HTTPConnectionPool(host='127.0.0.1', port=8000): Max retries exceeded with url: /:8000/endpoint_path (Caused by NewConnectionError('<urllib3.connection.HTTPConnection object at 0xffff831c0c90>: Failed to establish a new connection: [Errno 111] Connection refused'))
[2023-03-08T07:39:32.299+0000] {taskinstance.py:1323} INFO - Marking task as UP_FOR_RETRY. dag_id=dag_with_api, task_id=http_get, execution_date=20230306T000000, start_date=20230308T073931, end_date=20230308T073932
[2023-03-08T07:39:32.323+0000] {standard_task_runner.py:105} ERROR - Failed to execute job 51 for task http_get (HTTPConnectionPool(host='127.0.0.1', port=8000): Max retries exceeded with url: /:8000/endpoint_path (Caused by NewConnectionError('<urllib3.connection.HTTPConnection object at 0xffff831c0c90>: Failed to establish a new connection: [Errno 111] Connection refused')); 567)
[2023-03-08T07:39:32.354+0000] {local_task_job.py:208} INFO - Task exited with return code 1
[2023-03-08T07:39:32.412+0000] {taskinstance.py:2578} INFO - 0 downstream tasks scheduled from follow-on schedule check
